[2025-08-11T17:03:48.316+0000] {taskinstance.py:1979} INFO - Dependencies all met for dep_context=non-requeueable deps ti=<TaskInstance: ecommerce_sales_pipeline.transform_sales_data manual__2025-08-11T16:58:41.911902+00:00 [queued]>
[2025-08-11T17:03:48.323+0000] {taskinstance.py:1979} INFO - Dependencies all met for dep_context=requeueable deps ti=<TaskInstance: ecommerce_sales_pipeline.transform_sales_data manual__2025-08-11T16:58:41.911902+00:00 [queued]>
[2025-08-11T17:03:48.324+0000] {taskinstance.py:2193} INFO - Starting attempt 1 of 1
[2025-08-11T17:03:48.334+0000] {taskinstance.py:2217} INFO - Executing <Task(PythonOperator): transform_sales_data> on 2025-08-11 16:58:41.911902+00:00
[2025-08-11T17:03:48.338+0000] {standard_task_runner.py:60} INFO - Started process 714 to run task
[2025-08-11T17:03:48.341+0000] {standard_task_runner.py:87} INFO - Running: ['***', 'tasks', 'run', 'ecommerce_sales_pipeline', 'transform_sales_data', 'manual__2025-08-11T16:58:41.911902+00:00', '--job-id', '9', '--raw', '--subdir', 'DAGS_FOLDER/ecommerce_sales_pipeline.py', '--cfg-path', '/tmp/tmpa1dwgkd0']
[2025-08-11T17:03:48.343+0000] {standard_task_runner.py:88} INFO - Job 9: Subtask transform_sales_data
[2025-08-11T17:03:48.381+0000] {task_command.py:423} INFO - Running <TaskInstance: ecommerce_sales_pipeline.transform_sales_data manual__2025-08-11T16:58:41.911902+00:00 [running]> on host bbdd850e0279
[2025-08-11T17:03:48.438+0000] {taskinstance.py:2513} INFO - Exporting env vars: AIRFLOW_CTX_DAG_OWNER='***' AIRFLOW_CTX_DAG_ID='ecommerce_sales_pipeline' AIRFLOW_CTX_TASK_ID='transform_sales_data' AIRFLOW_CTX_EXECUTION_DATE='2025-08-11T16:58:41.911902+00:00' AIRFLOW_CTX_TRY_NUMBER='1' AIRFLOW_CTX_DAG_RUN_ID='manual__2025-08-11T16:58:41.911902+00:00'
[2025-08-11T17:03:48.440+0000] {taskinstance.py:2731} ERROR - Task failed with exception
Traceback (most recent call last):
  File "/opt/airflow/dags/ecommerce_sales_pipeline.py", line 37, in transform_sales_data
    time.sleep(10)
NameError: name 'time' is not defined

During handling of the above exception, another exception occurred:

Traceback (most recent call last):
  File "/home/airflow/.local/lib/python3.8/site-packages/airflow/models/taskinstance.py", line 444, in _execute_task
    result = _execute_callable(context=context, **execute_callable_kwargs)
  File "/home/airflow/.local/lib/python3.8/site-packages/airflow/models/taskinstance.py", line 414, in _execute_callable
    return execute_callable(context=context, **execute_callable_kwargs)
  File "/home/airflow/.local/lib/python3.8/site-packages/airflow/operators/python.py", line 200, in execute
    return_value = self.execute_callable()
  File "/home/airflow/.local/lib/python3.8/site-packages/airflow/operators/python.py", line 217, in execute_callable
    return self.python_callable(*self.op_args, **self.op_kwargs)
  File "/opt/airflow/dags/ecommerce_sales_pipeline.py", line 55, in transform_sales_data
    raise ValueError(f"Error transforming sales data: {e}")
ValueError: Error transforming sales data: name 'time' is not defined
[2025-08-11T17:03:48.449+0000] {taskinstance.py:1149} INFO - Marking task as FAILED. dag_id=ecommerce_sales_pipeline, task_id=transform_sales_data, execution_date=20250811T165841, start_date=20250811T170348, end_date=20250811T170348
[2025-08-11T17:03:48.458+0000] {standard_task_runner.py:107} ERROR - Failed to execute job 9 for task transform_sales_data (Error transforming sales data: name 'time' is not defined; 714)
[2025-08-11T17:03:48.473+0000] {local_task_job_runner.py:234} INFO - Task exited with return code 1
[2025-08-11T17:03:48.492+0000] {taskinstance.py:3312} INFO - 0 downstream tasks scheduled from follow-on schedule check
