[2025-08-11T17:04:14.910+0000] {taskinstance.py:1979} INFO - Dependencies all met for dep_context=non-requeueable deps ti=<TaskInstance: ecommerce_sales_pipeline.transform_sales_data manual__2025-08-11T17:04:11.537664+00:00 [queued]>
[2025-08-11T17:04:14.917+0000] {taskinstance.py:1979} INFO - Dependencies all met for dep_context=requeueable deps ti=<TaskInstance: ecommerce_sales_pipeline.transform_sales_data manual__2025-08-11T17:04:11.537664+00:00 [queued]>
[2025-08-11T17:04:14.918+0000] {taskinstance.py:2193} INFO - Starting attempt 1 of 1
[2025-08-11T17:04:14.932+0000] {taskinstance.py:2217} INFO - Executing <Task(PythonOperator): transform_sales_data> on 2025-08-11 17:04:11.537664+00:00
[2025-08-11T17:04:14.935+0000] {standard_task_runner.py:60} INFO - Started process 728 to run task
[2025-08-11T17:04:14.938+0000] {standard_task_runner.py:87} INFO - Running: ['***', 'tasks', 'run', 'ecommerce_sales_pipeline', 'transform_sales_data', 'manual__2025-08-11T17:04:11.537664+00:00', '--job-id', '11', '--raw', '--subdir', 'DAGS_FOLDER/ecommerce_sales_pipeline.py', '--cfg-path', '/tmp/tmplyqq3e2g']
[2025-08-11T17:04:14.939+0000] {standard_task_runner.py:88} INFO - Job 11: Subtask transform_sales_data
[2025-08-11T17:04:14.978+0000] {task_command.py:423} INFO - Running <TaskInstance: ecommerce_sales_pipeline.transform_sales_data manual__2025-08-11T17:04:11.537664+00:00 [running]> on host bbdd850e0279
[2025-08-11T17:04:15.034+0000] {taskinstance.py:2513} INFO - Exporting env vars: AIRFLOW_CTX_DAG_OWNER='***' AIRFLOW_CTX_DAG_ID='ecommerce_sales_pipeline' AIRFLOW_CTX_TASK_ID='transform_sales_data' AIRFLOW_CTX_EXECUTION_DATE='2025-08-11T17:04:11.537664+00:00' AIRFLOW_CTX_TRY_NUMBER='1' AIRFLOW_CTX_DAG_RUN_ID='manual__2025-08-11T17:04:11.537664+00:00'
[2025-08-11T17:04:15.036+0000] {taskinstance.py:2731} ERROR - Task failed with exception
Traceback (most recent call last):
  File "/opt/airflow/dags/ecommerce_sales_pipeline.py", line 37, in transform_sales_data
    time.sleep(10)
NameError: name 'time' is not defined

During handling of the above exception, another exception occurred:

Traceback (most recent call last):
  File "/home/airflow/.local/lib/python3.8/site-packages/airflow/models/taskinstance.py", line 444, in _execute_task
    result = _execute_callable(context=context, **execute_callable_kwargs)
  File "/home/airflow/.local/lib/python3.8/site-packages/airflow/models/taskinstance.py", line 414, in _execute_callable
    return execute_callable(context=context, **execute_callable_kwargs)
  File "/home/airflow/.local/lib/python3.8/site-packages/airflow/operators/python.py", line 200, in execute
    return_value = self.execute_callable()
  File "/home/airflow/.local/lib/python3.8/site-packages/airflow/operators/python.py", line 217, in execute_callable
    return self.python_callable(*self.op_args, **self.op_kwargs)
  File "/opt/airflow/dags/ecommerce_sales_pipeline.py", line 55, in transform_sales_data
    raise ValueError(f"Error transforming sales data: {e}")
ValueError: Error transforming sales data: name 'time' is not defined
[2025-08-11T17:04:15.046+0000] {taskinstance.py:1149} INFO - Marking task as FAILED. dag_id=ecommerce_sales_pipeline, task_id=transform_sales_data, execution_date=20250811T170411, start_date=20250811T170414, end_date=20250811T170415
[2025-08-11T17:04:15.055+0000] {standard_task_runner.py:107} ERROR - Failed to execute job 11 for task transform_sales_data (Error transforming sales data: name 'time' is not defined; 728)
[2025-08-11T17:04:15.070+0000] {local_task_job_runner.py:234} INFO - Task exited with return code 1
[2025-08-11T17:04:15.086+0000] {taskinstance.py:3312} INFO - 0 downstream tasks scheduled from follow-on schedule check
