[2025-08-11T16:58:45.099+0000] {taskinstance.py:1979} INFO - Dependencies all met for dep_context=non-requeueable deps ti=<TaskInstance: ecommerce_sales_pipeline.extract_sales_data manual__2025-08-11T16:58:41.911902+00:00 [queued]>
[2025-08-11T16:58:45.105+0000] {taskinstance.py:1979} INFO - Dependencies all met for dep_context=requeueable deps ti=<TaskInstance: ecommerce_sales_pipeline.extract_sales_data manual__2025-08-11T16:58:41.911902+00:00 [queued]>
[2025-08-11T16:58:45.106+0000] {taskinstance.py:2193} INFO - Starting attempt 1 of 4
[2025-08-11T16:58:45.116+0000] {taskinstance.py:2217} INFO - Executing <Task(PythonOperator): extract_sales_data> on 2025-08-11 16:58:41.911902+00:00
[2025-08-11T16:58:45.122+0000] {standard_task_runner.py:60} INFO - Started process 618 to run task
[2025-08-11T16:58:45.125+0000] {standard_task_runner.py:87} INFO - Running: ['***', 'tasks', 'run', 'ecommerce_sales_pipeline', 'extract_sales_data', 'manual__2025-08-11T16:58:41.911902+00:00', '--job-id', '3', '--raw', '--subdir', 'DAGS_FOLDER/ecommerce_sales_pipeline.py', '--cfg-path', '/tmp/tmp6wy7trrq']
[2025-08-11T16:58:45.127+0000] {standard_task_runner.py:88} INFO - Job 3: Subtask extract_sales_data
[2025-08-11T16:58:45.168+0000] {task_command.py:423} INFO - Running <TaskInstance: ecommerce_sales_pipeline.extract_sales_data manual__2025-08-11T16:58:41.911902+00:00 [running]> on host bbdd850e0279
[2025-08-11T16:58:45.231+0000] {taskinstance.py:2513} INFO - Exporting env vars: AIRFLOW_CTX_DAG_EMAIL='your_email@example.com' AIRFLOW_CTX_DAG_OWNER='***' AIRFLOW_CTX_DAG_ID='ecommerce_sales_pipeline' AIRFLOW_CTX_TASK_ID='extract_sales_data' AIRFLOW_CTX_EXECUTION_DATE='2025-08-11T16:58:41.911902+00:00' AIRFLOW_CTX_TRY_NUMBER='1' AIRFLOW_CTX_DAG_RUN_ID='manual__2025-08-11T16:58:41.911902+00:00'
[2025-08-11T16:58:45.236+0000] {taskinstance.py:2731} ERROR - Task failed with exception
Traceback (most recent call last):
  File "/opt/airflow/dags/ecommerce_sales_pipeline.py", line 24, in extract_sales_data
    sales_data = pd.read_csv('tmp/source_data/sales_data.csv')
  File "/home/airflow/.local/lib/python3.8/site-packages/pandas/io/parsers/readers.py", line 912, in read_csv
    return _read(filepath_or_buffer, kwds)
  File "/home/airflow/.local/lib/python3.8/site-packages/pandas/io/parsers/readers.py", line 577, in _read
    parser = TextFileReader(filepath_or_buffer, **kwds)
  File "/home/airflow/.local/lib/python3.8/site-packages/pandas/io/parsers/readers.py", line 1407, in __init__
    self._engine = self._make_engine(f, self.engine)
  File "/home/airflow/.local/lib/python3.8/site-packages/pandas/io/parsers/readers.py", line 1661, in _make_engine
    self.handles = get_handle(
  File "/home/airflow/.local/lib/python3.8/site-packages/pandas/io/common.py", line 859, in get_handle
    handle = open(
FileNotFoundError: [Errno 2] No such file or directory: 'tmp/source_data/sales_data.csv'

During handling of the above exception, another exception occurred:

Traceback (most recent call last):
  File "/home/airflow/.local/lib/python3.8/site-packages/airflow/models/taskinstance.py", line 444, in _execute_task
    result = _execute_callable(context=context, **execute_callable_kwargs)
  File "/home/airflow/.local/lib/python3.8/site-packages/airflow/models/taskinstance.py", line 414, in _execute_callable
    return execute_callable(context=context, **execute_callable_kwargs)
  File "/home/airflow/.local/lib/python3.8/site-packages/airflow/operators/python.py", line 200, in execute
    return_value = self.execute_callable()
  File "/home/airflow/.local/lib/python3.8/site-packages/airflow/operators/python.py", line 217, in execute_callable
    return self.python_callable(*self.op_args, **self.op_kwargs)
  File "/opt/airflow/dags/ecommerce_sales_pipeline.py", line 27, in extract_sales_data
    raise ValueError(f"Error loading sales data fromCSV: {e}")
ValueError: Error loading sales data fromCSV: [Errno 2] No such file or directory: 'tmp/source_data/sales_data.csv'
[2025-08-11T16:58:45.246+0000] {taskinstance.py:1149} INFO - Marking task as UP_FOR_RETRY. dag_id=ecommerce_sales_pipeline, task_id=extract_sales_data, execution_date=20250811T165841, start_date=20250811T165845, end_date=20250811T165845
[2025-08-11T16:58:45.257+0000] {standard_task_runner.py:107} ERROR - Failed to execute job 3 for task extract_sales_data (Error loading sales data fromCSV: [Errno 2] No such file or directory: 'tmp/source_data/sales_data.csv'; 618)
[2025-08-11T16:58:45.297+0000] {local_task_job_runner.py:234} INFO - Task exited with return code 1
[2025-08-11T16:58:45.317+0000] {taskinstance.py:3312} INFO - 0 downstream tasks scheduled from follow-on schedule check
